File: DAQ- Crosshead, … - (Timed).txt
File Path: C:\Users\apk5101\Desktop\cbPDMS_005ppt_Oven_65C_3 01-10-22 14 05 58 PM\DAQ- Crosshead, … - (Timed).txt
Test: MTS EM Tension (Simplified) with Video Extensometer apk5101 5
Test Run: cbPDMS_005ppt_Oven_65C_3_csa10.01
Date: 1/10/2022 12:52:17 PM


Crosshead 	Load 	Time 	Strain 1 	Video Time
mm	N	sec	mm/mm	sec
0.0863599707372487	-0.255385667085648	0.112000003457069	-5.38021004103939E-06	8.19979953765869
0.17039715021383	-0.222434714436531	0.211999997496605	-5.38021004103939E-06	8.29979991912842
0.254374783253297	0.232145354151726	0.312000006437302	0.00251919007860124	8.39980030059814
0.338292855303735	-0.191524773836136	0.412000000476837	0.00251919007860124	8.49979972839355
0.421913136960939	0.104812853038311	0.512000024318695	0.00408317986875772	8.59980010986328
0.505771662574261	-0.420824259519577	0.611999988555908	0.00565120996907353	8.69979953765869
0.588975031860173	-0.194381162524223	0.712000012397766	0.00691701006144285	8.79979991912842
0.673012167681009	-0.0797787606716156	0.811999976634979	0.00913652963936329	8.89990043640137
0.756453780923039	0.162145614624023	0.912000000476837	0.0103379003703594	8.99979972839355
0.840074091684073	-0.0692948400974274	1.01199996471405	0.0115865003317595	9.09980010986328
0.923396553844213	0.296721637248993	1.11199998855591	0.0127772996202111	9.19979953765869
1.00665946956724	-0.352833986282349	1.21200001239777	0.0143932998180389	9.29979991912842
1.09016068745404	0.479640454053879	1.31200003623962	0.0156945995986462	9.39980030059814
1.17348309140652	-0.136880069971085	1.41199994087219	0.0169572997838259	9.49979972839355
1.25710340216756	0.0189057663083076	1.51199996471405	0.0199369005858898	9.59980010986328
1.34060450363904	0.325448513031006	1.61199998855591	0.0199369005858898	9.69979953765869
1.42356962896883	0.0640239492058754	1.71200001239777	0.021688599139452	9.79979991912842
1.50718993972987	0.385842800140381	1.81200003623962	0.0230541992932558	9.89980030059814
1.59033376257867	-0.483249068260193	1.91199994087219	0.0242934003472328	9.99979972839355
1.67389446869493	0.861664235591888	2.01200008392334	0.0276234000921249	10.0998001098633
1.75733608193696	-0.733137667179108	2.11199998855591	0.0276234000921249	10.1997995376587
1.84071809053421	0.125280946493149	2.21199989318848	0.0303879994899035	10.2996997833252
1.92386191338301	0.175449088215828	2.31200003623962	0.0303879994899035	10.3998003005981
2.00736313126981	0.0934557169675827	2.41199994087219	0.0319490991532803	10.4997997283936
2.09068553522229	-0.0901364237070084	2.51200008392334	0.0335281006991863	10.5998001098633
2.17406754381955	0.25561711192131	2.61199998855591	0.0348673015832901	10.6997995376587
2.25715176202357	0.681033670902252	2.71199989318848	0.0363290011882782	10.7997999191284
2.3408317938447	0.26650607585907	2.81200003623962	0.0378171987831593	10.8998003005981
2.42385640740395	1.34329307079315	2.91199994087219	0.0393614992499352	10.9997997283936
2.50729802064598	0.572144031524658	3.01200008392334	0.0406452007591724	11.0996999740601
2.59050144813955	1.16993236541748	3.11199998855591	0.0423413999378681	11.1997995376587
2.6738834567368	0.439056694507599	3.21199989318848	0.0437541007995605	11.2996997833252
2.75708665139973	0.447788923978806	3.31200003623962	0.0450503006577492	11.3998003005981
2.8402900788933	1.44459736347198	3.41199994087219	0.0480373986065388	11.4997997283936
2.92396987788379	0.830449223518372	3.51200008392334	0.0480373986065388	11.5998001098633
3.00735188648105	1.02403080463409	3.61199998855591	0.0495803989470005	11.6997995376587
3.09049570932984	0.787808656692505	3.71199989318848	0.0511348992586136	11.7997999191284
3.17435432225466	0.873031914234161	3.81200003623962	0.0525273010134697	11.8998003005981
3.25708114542067	1.16017436981201	3.91199994087219	0.0554738007485867	11.9996995925903
3.34058236330748	0.448430687189102	4.01200008392334	0.0554738007485867	12.0998001098633
3.42396437190473	0.577735841274261	4.11199998855591	0.0572151988744736	12.1997995376587
3.50710819475353	0.542133629322052	4.21199989318848	0.0586629994213581	12.2996997833252
3.59060941264033	1.22676539421082	4.31199979782104	0.0600881986320019	12.3997001647949
3.67381284013391	1.31393504142761	4.41200017929077	0.0616302005946636	12.4996995925903
3.75737342983484	1.21929037570953	4.51200008392334	0.0629654973745346	12.5998001098633
3.84057685732841	0.721391260623932	4.61199998855591	0.065999798476696	12.6997995376587
3.92383988946676	1.43506550788879	4.71199989318848	0.065999798476696	12.7996997833252
4.00728126987815	0.833458125591278	4.81199979782104	0.0675309002399445	12.8998003005981
4.09042509272695	1.52831077575684	4.91200017929077	0.0690599009394646	12.9997997283936
4.17362852022052	1.06616640090942	5.01200008392334	0.0703997015953064	13.1079998016357
4.25730831921101	0.869570553302765	5.11199998855591	0.0734774023294449	13.1997003555298
4.34051174670458	0.899470508098602	5.21199989318848	0.0734774023294449	13.2996997833252
4.42389398813248	1.54946804046631	5.31199979782104	0.0763607025146484	13.3997001647949
4.50709694996476	0.813142597675323	5.41200017929077	0.0763607025146484	13.4996995925903
4.59065800532699	1.57293450832367	5.51200008392334	0.0780249983072281	13.5998001098633
4.67380182817578	1.51216149330139	5.61199998855591	0.0794005021452904	13.6998996734619
4.75724320858717	1.23506104946136	5.71199989318848	0.0810265988111496	13.7996997833252
4.84062545001507	1.64578008651733	5.81199979782104	0.0838598012924194	13.8997001647949
4.92370966821909	0.729239702224731	5.91200017929077	0.0838598012924194	13.9996995925903
5.0073298625648	1.58704805374146	6.01200008392334	0.0855790004134178	14.0998001098633
5.09053329005837	1.36058390140533	6.11199998855591	0.0869401022791862	14.1997003555298
5.17415348440409	1.96369576454163	6.21199989318848	0.0887024030089378	14.2996997833252
5.25735691189766	2.03744101524353	6.31199979782104	0.0901061967015266	14.3998003005981
5.3401431068778	1.43058371543884	6.41200017929077	0.0913954973220825	14.4996995925903
5.42400171980262	1.15311503410339	6.51200008392334	0.0944247990846634	14.5996999740601
5.50714554265141	2.06141233444214	6.61199998855591	0.0944247990846634	14.6997995376587
5.59046817943454	1.98541581630707	6.71199989318848	0.0958866998553276	14.7996997833252
5.67402876913548	1.6474529504776	6.81199979782104	0.0974363014101982	14.8997001647949
5.7573514059186	1.56622231006622	6.91200017929077	0.0988401025533676	14.9996995925903
5.84043562412262	1.33187806606293	7.01200008392334	0.101853996515274	15.0996999740601
5.92387700453401	1.91366970539093	7.11199998855591	0.101853996515274	15.1997003555298
6.00737845525146	1.81635284423828	7.21199989318848	0.104846000671387	15.2996997833252
6.09064102172852	2.44814944267273	7.31199979782104	0.104846000671387	15.3997001647949
6.17360649630427	1.60208749771118	7.41200017929077	0.10639800131321	15.4996995925903
6.25764345750213	2.04437398910522	7.51200008392334	0.107882998883724	15.5996999740601
6.34043011814356	1.95033442974091	7.61199998855591	0.109511002898216	15.6997003555298
6.42369268462062	2.1393711566925	7.71199989318848	0.112455002963543	15.799599647522
6.50737294927239	2.2330002784729	7.81199979782104	0.112455002963543	15.8998003005981
6.59075472503901	1.72032475471497	7.91200017929077	0.113968998193741	15.9996995925903
6.67395815253258	2.32008051872253	8.01200008392334	0.115350998938084	16.0997009277344
6.7572807893157	2.08155965805054	8.11200046539307	0.116982996463776	16.1996994018555
6.84084137901664	2.05036568641663	8.21199989318848	0.118326999247074	16.2996997833252
6.92404480651021	1.56263470649719	8.3120002746582	0.119961000978947	16.3997001647949
7.00706942006946	2.6768913269043	8.41199970245361	0.1214369982481	16.3997001647949
7.09074921905994	2.23017024993896	8.51200008392334	0.122784003615379	16.5998001098633
7.17341667041183	2.73410320281982	8.61200046539307	0.124301001429558	16.6996994018555
7.25709646940231	2.18481016159058	8.71199989318848	0.125724002718925	16.7996997833252
7.3405378498137	1.63279223442078	8.8120002746582	0.127188995480537	16.8997001647949
7.42380088195205	1.91359078884125	8.91199970245361	0.128745004534721	16.9995994567871
7.50730186700821	2.5125732421875	9.01200008392334	0.130151003599167	17.0997009277344
7.59050529450178	2.19742441177368	9.11200046539307	0.133101999759674	17.1996002197266
7.67388753592968	2.17549920082092	9.21199989318848	0.133101999759674	17.2996006011963
7.75715056806803	2.3279869556427	9.3120002746582	0.134562000632286	17.3995990753174
7.8403539955616	2.03812479972839	9.41199970245361	0.136070996522903	17.4997005462646
7.9237362369895	2.44959616661072	9.51200008392334	0.137490004301071	17.5995998382568
8.00723675638437	2.89736390113831	9.61200046539307	0.140423998236656	17.6996002197266
8.09049978852272	2.47338342666626	9.71199989318848	0.140423998236656	17.7996997833252
8.17406084388494	2.48183155059814	9.8120002746582	0.141895994544029	17.8997001647949
8.25762096792459	2.4377338886261	9.91199970245361	0.143480002880096	17.9995994567871
8.34082439541817	1.90547931194305	10.0120000839233	0.14487299323082	18.0997009277344
8.42378940433264	2.26458883285522	10.1120004653931	0.147786006331444	18.1996002197266
8.50735045969486	2.41453051567078	10.2119998931885	0.147786006331444	18.2996006011963
8.59049428254366	2.95611691474915	10.3120002746582	0.150858998298645	18.3995990753174
8.67399573326111	2.42923331260681	10.4119997024536	0.150858998298645	18.4995994567871
8.75743757933378	2.30001759529114	10.5120000839233	0.152336001396179	18.6026992797852
8.84075928479433	2.21791887283325	10.6120004653931	0.153826996684074	18.6996002197266
8.92414152622223	2.46619248390198	10.7119998931885	0.155339002609253	18.7996006011963
9.00740455836058	2.54891705513	10.8120002746582	0.158225998282433	18.8995990753174
9.09066759049892	2.29779767990112	10.9119997024536	0.158225998282433	18.9997005462646
9.17375180870295	2.8136031627655	11.0120000839233	0.161134004592896	19.0995998382568
9.25677642226219	2.30270028114319	11.1120004653931	0.161134004592896	19.1996002197266
9.34075377881527	2.51668691635132	11.2119998931885	0.162589997053146	19.2996006011963
9.42401681095362	2.1119909286499	11.3120002746582	0.165396004915237	19.3995990753174
9.50722023844719	2.9398045539856	11.4119997024536	0.165396004915237	19.4995994567871
9.59096010774374	2.45122671127319	11.5120000839233	0.1683109998703	19.5997009277344
9.67398472130299	2.94784235954285	11.6120004653931	0.1683109998703	19.6996002197266
9.75712854415178	2.19506788253784	11.7119998931885	0.169770002365112	19.7996006011963
9.84056945890188	2.91461801528931	11.8120002746582	0.171211004257202	19.8995990753174
9.92383249104023	3.18651604652405	11.9119997024536	0.172773003578186	19.9995994567871
10.0073935464025	2.51983785629272	12.0120000839233	0.174224004149437	20.0997009277344
10.0904777646065	2.66209387779236	12.1120004653931	0.175447002053261	20.1996002197266
10.1745147258043	3.32130241394043	12.2119998931885	0.177157998085022	20.1996002197266
10.2573009207845	3.11649513244629	12.3120002746582	0.178610995411873	20.3995990753174
10.3408023715019	2.67715954780579	12.4119997024536	0.180095002055168	20.4995994567871
10.424125008285	3.02407574653625	12.5120000839233	0.181398004293442	20.5995006561279
10.5076264590025	2.76186728477478	12.6120004653931	0.183035001158714	20.6996002197266
10.5905318632722	3.45234346389771	12.7119998931885	0.185807004570961	20.7994995117188
10.673675686121	2.95704817771912	12.8120002746582	0.185807004570961	20.8995990753174
10.7572358101606	2.96050405502319	12.9119997024536	0.18885999917984	20.9995994567871
10.8404392376542	3.33846688270569	13.0120000839233	0.18885999917984	21.0995998382568
10.9236426651478	2.56189966201782	13.1120004653931	0.190273001790047	21.1996994018555
11.0076209530234	3.25819373130798	13.2119998931885	0.193239003419876	21.2996006011963
11.0903475433588	3.03189778327942	13.3120002746582	0.193239003419876	21.3995990753174
11.1739682033658	2.80165672302246	13.4119997024536	0.196173995733261	21.4995002746582
11.2573495134711	3.16573739051819	13.5120000839233	0.196173995733261	21.5995998382568
11.3404337316751	3.04142451286316	13.6120004653931	0.197626993060112	21.6996002197266
11.4239351823926	3.39407968521118	13.7119998931885	0.200555995106697	21.7996006011963
11.5070790052414	3.51671981811523	13.8120002746582	0.200555995106697	21.8995990753174
11.5904612466693	3.63105392456055	13.9119997024536	0.203648999333382	21.9995994567871
11.673903092742	3.51040744781494	14.0120000839233	0.203648999333382	22.0995998382568
11.7572247982025	3.74840760231018	14.1120004653931	0.205063000321388	22.1996002197266
11.8405474349856	3.73745012283325	14.2119998931885	0.206705003976822	22.2996006011963
11.9240488857031	4.06647062301636	14.3120002746582	0.208098992705345	22.3995990753174
12.0073119178414	3.70687174797058	14.4119997024536	0.209535002708435	22.4995994567871
12.0906345546246	3.92664980888367	14.5120000839233	0.210969999432564	22.5995006561279
12.1739562600851	3.68120622634888	14.6120004653931	0.21390700340271	22.699499130249
12.2572788968682	3.49820327758789	14.7119998931885	0.21390700340271	22.7994995117188
12.3404823243618	3.31709933280945	14.8120002746582	0.215378999710083	22.8995990753174
12.4241029843688	3.66672968864441	14.9119997024536	0.216762006282806	22.9995002746582
12.507127597928	3.94900107383728	15.0120000839233	0.218142002820969	23.0995006561279
12.5906290486455	4.02561330795288	15.1120004653931	0.219570994377136	23.1996002197266
12.6740103587508	3.95246767997742	15.2119998931885	0.220965996384621	23.2994995117188
12.7573329955339	3.86652898788452	15.3120002746582	0.222479000687599	23.2994995117188
12.8405364230275	3.9627833366394	15.4119997024536	0.223960995674133	23.4995002746582
12.9236206412315	3.09009337425232	15.5120000839233	0.225325003266335	23.5995006561279
13.0070028826594	3.94344615936279	15.6120004653931	0.226821005344391	23.699499130249
13.0903851240873	3.50150156021118	15.7119998931885	0.22825500369072	23.7994995117188
13.1735885515809	3.32165479660034	15.8120002746582	0.231216996908188	23.8994998931885
13.2573870941997	3.28141832351685	15.9119997024536	0.231216996908188	23.9995002746582
13.3407693356276	3.60034918785095	16.011999130249	0.232636004686356	24.0995998382568
13.4240919724107	3.73329448699951	16.1119995117188	0.234073996543884	24.199499130249
13.507355004549	3.81141090393066	16.2119998931885	0.23556199669838	24.2994995117188
13.5903200134635	3.98681259155273	16.3120002746582	0.237053006887436	24.3995990753174
13.6735830456018	3.56244301795959	16.4120006561279	0.23845499753952	24.4993991851807
13.7569047510624	3.98258852958679	16.511999130249	0.239858999848366	24.4993991851807
13.8405850157142	3.74384689331055	16.6119995117188	0.241323992609978	24.699499130249
13.9240268617868	4.04739618301392	16.7119998931885	0.243003994226456	24.7994995117188
14.0075273811817	3.85322046279907	16.8120002746582	0.244384005665779	24.8994998931885
14.0911480411887	4.04423999786377	16.9120006561279	0.245701998472214	24.9995002746582
14.1738150268793	3.42965030670166	17.011999130249	0.247087001800537	24.9995002746582
14.2573760822415	4.15854787826538	17.1119995117188	0.24847300350666	25.199499130249
14.3402814865112	3.54037570953369	17.2119998931885	0.251390993595123	25.2994995117188
14.423961751163	3.57300567626953	17.3120002746582	0.251390993595123	25.3994007110596
14.5071055740118	4.2552809715271	17.4120006561279	0.252743005752563	25.4995002746582
14.5904878154397	3.79994869232178	17.511999130249	0.255699992179871	25.5993995666504
14.6739883348346	4.05954790115356	17.6119995117188	0.255699992179871	25.699499130249
14.7573705762625	3.67138004302979	17.7119998931885	0.2569679915905	25.699499130249
14.8406932130456	3.67529892921448	17.8120002746582	0.258547008037567	25.8994998931885
14.9245513603091	4.33463335037231	17.9120006561279	0.259889006614685	25.9995002746582
15.0072192773223	4.10514974594116	18.011999130249	0.261307001113892	26.0995006561279
15.0906005874276	4.1578221321106	18.1119995117188	0.262787997722626	26.199499130249
15.1735665276647	4.17710638046265	18.2119998931885	0.265605002641678	26.2994995117188
15.2568882331252	3.90113711357117	18.3120002746582	0.265605002641678	26.3994007110596
15.3403300791979	4.24122524261475	18.4120006561279	0.268373996019363	26.4995002746582
15.4238911345601	3.55440521240234	18.511999130249	0.268373996019363	26.5995006561279
15.5074512585998	4.33358144760132	18.6119995117188	0.269865989685059	26.6993999481201
15.5906546860933	4.11768007278442	18.7119998931885	0.271293997764587	26.7994003295898
15.6740378588438	4.35290288925171	18.8120002746582	0.272785007953644	26.8994998931885
15.75718075037	4.01327228546143	18.9120006561279	0.275765985250473	26.9993991851807
15.8405620604753	4.58231782913208	19.011999130249	0.275765985250473	27.0995006561279
15.9237068146467	4.21889495849609	19.1119995117188	0.277040004730225	27.0995006561279
16.0067304968834	4.32143545150757	19.2119998931885	0.278465002775192	27.2994003295898
16.0906501114368	4.33215570449829	19.3120002746582	0.279774993658066	27.3994998931885
16.1740910261869	4.32104063034058	19.4120006561279	0.280927002429962	27.4995002746582
16.2571761757135	4.28733777999878	19.511999130249	0.282831013202667	27.5993995666504
16.3406766951084	4.40954113006592	19.6119995117188	0.285533010959625	27.6993999481201
16.4237003773451	4.21994686126709	19.7119998931885	0.285533010959625	27.7994003295898
16.5073815733194	4.46012496948242	19.8120002746582	0.286983013153076	27.8994007110596
16.5906436741352	4.33315563201904	19.9120006561279	0.288345992565155	27.9993991851807
16.6738480329514	4.88884496688843	20.011999130249	0.289732992649078	28.0995006561279
16.7571697384119	4.75485277175903	20.1119995117188	0.292557001113892	28.1993999481201
16.8405510485172	4.6530909538269	20.2119998931885	0.292557001113892	28.2994003295898
16.9239938259125	4.5318660736084	20.3120002746582	0.295392990112305	28.3994007110596
17.0072559267282	4.74099159240723	20.4120006561279	0.295392990112305	28.4993991851807
17.0904006808996	4.45368099212646	20.511999130249	0.296864002943039	28.5995006561279
17.174020409584	4.22000503540039	20.6119995117188	0.298281997442245	28.699499130249
17.2574613243341	5.25934839248657	20.7119998931885	0.299620002508163	28.7994003295898
17.3407252877951	4.56527423858643	20.8120002746582	0.302457988262177	28.8994998931885
17.4239277839661	4.14480781555176	20.9120006561279	0.302457988262177	28.9993991851807
17.5071321427822	4.65725183486938	21.011999130249	0.303966999053955	29.0993995666504
17.5902750343084	4.84473705291748	21.1119995117188	0.305047988891602	29.1993999481201
17.6737178117037	4.86679363250732	21.2119998931885	0.306665986776352	29.2994003295898
17.7572779357433	5.00556755065918	21.3120002746582	0.308097004890442	29.3994007110596
17.8405400365591	4.74463176727295	21.4120006561279	0.309132993221283	29.4993991851807
17.9240424185991	5.11291551589966	21.511999130249	0.310934007167816	29.4993991851807
18.0076025426388	4.78185415267944	21.6119995117188	0.312108993530273	29.6993999481201
18.0902704596519	4.32849979400635	21.7119998931885	0.313630998134613	29.7994003295898
18.1738305836916	4.74460029602051	21.8120002746582	0.315097987651825	29.899299621582
18.2570330798626	4.75718832015991	21.9120006561279	0.316179990768433	29.9993000030518
18.3406546711922	4.82935047149658	22.011999130249	0.319218993186951	30.1004009246826
18.4242147952318	4.87547826766968	22.1119995117188	0.319218993186951	30.1993007659912
18.5072403401136	4.96192741394043	22.2119998931885	0.320504009723663	30.2992992401123
18.5907408595085	5.00200080871582	22.3120002746582	0.322167009115219	30.3994007110596
18.6741221696138	5.28508234024048	22.4120006561279	0.323336988687515	30.4993991851807
18.7570881098509	4.9989972114563	22.511999130249	0.324629008769989	30.5993003845215
18.8410058617592	5.37474012374878	22.6119995117188	0.326126992702484	30.6993007659912
18.9237929880619	4.843505859375	22.7119998931885	0.329932987689972	30.7992992401123
19.0075319260359	4.53920412063599	22.8120002746582	0.329932987689972	30.899299621582
19.0907344222069	5.31095266342163	22.9120006561279	0.331162005662918	30.9993000030518
19.1739983856678	4.69666290283203	23.011999130249	0.33236700296402	31.0995006561279
19.2573200911283	4.58273887634277	23.1119995117188	0.333555996417999	31.1993007659912
19.3408224731684	5.07486724853516	23.2119998931885	0.334903985261917	31.2992992401123
19.4239653646946	4.65181255340576	23.3120002746582	0.336158990859985	31.399299621582
19.507110118866	4.82548904418945	23.4120006561279	0.337417989969254	31.4993000030518
19.5904318243265	4.92404747009277	23.511999130249	0.338717013597488	31.5993003845215
19.6736957877874	5.546959400177	23.6119995117188	0.340054988861084	31.6993999481201
19.7570770978928	4.44844150543213	23.7119998931885	0.341026991605759	31.7992992401123
19.8405180126429	5.42339849472046	23.8120002746582	0.342182010412216	31.899299621582
19.9236627668142	5.00231122970581	23.9120006561279	0.345120996236801	31.9993000030518
20.0071632862091	5.33019018173218	24.011999130249	0.345120996236801	32.0993003845215
20.090663805604	5.20570850372314	24.1119995117188	0.345696002244949	32.1992988586426
20.1738085597754	5.54850578308105	24.2119998931885	0.348320990800858	32.2993011474609
20.2575474977493	5.68789529800415	24.3120002746582	0.349424988031387	32.3993988037109
20.3403942286968	5.31876468658447	24.4120006561279	0.351043999195099	32.4992980957031
20.4238947480917	4.83084964752197	24.511999130249	0.352479010820389	32.5993003845215
20.5074548721313	4.93204832077026	24.6119995117188	0.353803008794785	32.6992988586426
20.5906592309475	5.22093200683594	24.7119998931885	0.355194002389908	32.7993011474609
20.6741001456976	5.81420707702637	24.8120002746582	0.356445014476776	32.899299621582
20.757244899869	5.88855171203613	24.9120006561279	0.358060002326965	32.9992980957031
20.8405070006847	5.43329858779907	25.011999130249	0.359360009431839	33.0993003845215
20.9238305687904	5.60524415969849	25.1119995117188	0.362156003713608	33.1992988586426
21.0070926696062	5.27260494232178	25.2119998931885	0.362156003713608	33.2993011474609
21.0907720029354	5.33000564575195	25.3120002746582	0.363384008407593	33.399299621582
21.1739763617516	4.94956541061401	25.4120006561279	0.364735990762711	33.4992980957031
21.2571192532778	6.00063991546631	25.511999130249	0.366095006465912	33.5993003845215
21.3407408446074	6.03397464752197	25.6119995117188	0.368616014719009	33.6991996765137
21.423764526844	5.50176763534546	25.7119998931885	0.368616014719009	33.7993011474609
21.5070880949497	6.37418937683105	25.8120002746582	0.372866004705429	33.8992004394531
21.5902309864759	5.6526346206665	25.9120006561279	0.372866004705429	33.9992980957031
21.6740295290947	5.54055738449097	26.011999130249	0.372743010520935	34.0993003845215
21.7572338879108	5.33228349685669	26.1119995117188	0.374049007892609	34.1992988586426
21.8406151980162	5.85409116744995	26.2119998931885	0.375423014163971	34.2993011474609
21.9243541359901	6.29497861862183	26.3120002746582	0.378105014562607	34.3992004394531
22.006843239069	5.8560848236084	26.4120006561279	0.378105014562607	34.4992980957031
22.0907013863325	5.66989946365356	26.511999130249	0.379260003566742	34.5992012023926
22.1737865358591	5.53545475006104	26.6119995117188	0.380225002765656	34.6992988586426
22.257287055254	5.96260213851929	26.7119998931885	0.382214993238449	34.7991981506348
22.340789437294	5.83775758743286	26.8120002746582	0.383581012487411	34.8992004394531
22.4238727241755	6.07020807266235	26.9120006561279	0.384451001882553	34.9991989135742
22.5073136389256	5.95671033859253	27.011999130249	0.387618005275726	35.0992012023926
22.5906372070313	5.36448240280151	27.1119995117188	0.387618005275726	35.1992988586426
22.6737204939127	5.83923053741455	27.2119998931885	0.388529986143112	35.2991981506348
22.7575208991766	5.8567214012146	27.3120002746582	0.390242010354996	35.3992004394531
22.840604186058	5.59863185882568	27.4120006561279	0.39164999127388	35.4991989135742
22.9241047054529	5.84623241424561	27.511999130249	0.394145995378494	35.5992012023926
23.0071898549795	6.04757261276245	27.6119995117188	0.394145995378494	35.6991996765137
23.0906307697296	5.80540657043457	27.7119998931885	0.395500987768173	35.7991981506348
23.1738351285458	5.88050889968872	27.8120002746582	0.396739989519119	35.8992004394531
23.2570972293615	5.53652286529541	27.9120006561279	0.398056000471115	35.9991989135742
23.3407765626907	5.92032432556152	28.011999130249	0.399396002292633	36.0993003845215
23.4239213168621	5.93419075012207	28.1119995117188	0.400756001472473	36.1991996765137
23.5070642083883	5.91212892532349	28.2119998931885	0.403393000364304	36.2991981506348
23.5906857997179	5.97160243988037	28.3120002746582	0.403393000364304	36.399299621582
23.6739479005337	5.32163667678833	28.4120006561279	0.404599010944366	36.399299621582
23.7574502825737	6.02538967132568	28.511999130249	0.405975997447968	36.5992012023926
23.8401759415865	6.38863945007324	28.6119995117188	0.407328009605408	36.6991996765137
23.9239744842052	6.28686714172363	28.7119998931885	0.409947991371155	36.7991981506348
24.0072384476662	6.90593862533569	28.8120002746582	0.409947991371155	36.8992004394531
24.0903813391924	6.26083850860596	28.9120006561279	0.410946011543274	36.9991989135742
24.1742413491011	6.03754663467407	29.011999130249	0.412209987640381	37.0992012023926
24.2570862174034	5.67544889450073	29.1119995117188	0.413599997758865	37.1991996765137
24.3403501808643	6.54990673065186	29.2119998931885	0.414860993623734	37.2991981506348
24.4240891188383	6.25394773483276	29.3120002746582	0.415922999382019	37.3992004394531
24.5072320103645	6.0502610206604	29.4120006561279	0.417504996061325	37.4991989135742
24.5905555784702	6.0596718788147	29.511999130249	0.418734014034271	37.5992012023926
24.6739368885756	6.23307991027832	29.6119995117188	0.420082002878189	37.6991996765137
24.7572604566813	6.31891298294067	29.7119998931885	0.421388000249863	37.7991981506348
24.8407013714314	6.42384719848633	29.8120002746582	0.422170013189316	37.8991012573242
24.9237846583128	6.74031591415405	29.9120006561279	0.423887997865677	37.9990997314453
25.007227435708	6.4228687286377	30.011999130249	0.42519599199295	38.0992012023926
25.0906087458134	6.57948541641235	30.1119995117188	0.427754014730453	38.1991996765137
25.1739323139191	6.52645587921143	30.2119998931885	0.427754014730453	38.2991981506348
25.2573732286692	6.91520738601685	30.3120002746582	0.42892000079155	38.3992004394531
25.3406949341297	6.83108377456665	30.4120006561279	0.430368989706039	38.4991989135742
25.4240185022354	6.64136838912964	30.511999130249	0.431591004133224	38.5992012023926
25.5071613937616	6.76294612884521	30.6119995117188	0.432790994644165	38.6991996765137
25.5907233804464	6.41960191726685	30.7119998931885	0.434058994054794	38.7991981506348
25.6736874580383	6.64565563201904	30.8120002746582	0.435335993766785	38.8991012573242
25.7571898400784	7.15288162231445	30.9120006561279	0.436699002981186	38.9991989135742
25.8409287780523	6.63903284072876	31.011999130249	0.43799901008606	39.0990982055664
25.9238332509995	6.50575637817383	31.1119995117188	0.439444988965988	39.1991996765137
26.0073356330395	7.35945081710815	31.2119998931885	0.440324991941452	39.2990989685059
26.0905381292105	6.698317527771	31.3120002746582	0.442952990531921	39.3991012573242
26.1739213019609	6.82375621795654	31.4120006561279	0.442952990531921	39.4990997314453
26.2574814260006	6.69221019744873	31.511999130249	0.444328993558884	39.4990997314453
26.3402685523033	6.92917919158936	31.6119995117188	0.44574299454689	39.6991004943848
26.4234710484743	7.04118299484253	31.7119998931885	0.446128010749817	39.7990989685059
26.5073888003826	6.63107395172119	31.8120002746582	0.448177009820938	39.8992004394531
26.5902951359749	6.76405620574951	31.9120006561279	0.449319005012512	39.9990997314453
26.674272492528	7.43755149841309	32.0120010375977	0.450453013181686	39.9990997314453
26.757238432765	6.5861029624939	32.1119995117188	0.451714009046555	40.1991004943848
26.8408581614494	6.8592529296875	32.2120018005371	0.453000009059906	40.2990989685059
26.9240010529757	7.43326473236084	32.3120002746582	0.453871011734009	40.3991012573242
27.0076226443052	7.06742143630981	32.4119987487793	0.455303996801376	40.4990997314453
27.0909443497658	7.3815131187439	32.5120010375977	0.456396013498306	40.5992012023926
27.173850685358	6.2562255859375	32.6119995117188	0.457812994718552	40.6991004943848
27.2573512047529	7.0272798538208	32.7120018005371	0.458968013525009	40.7990989685059
27.3403748869896	6.81720161437988	32.8120002746582	0.460119992494583	40.8991012573242
27.4237580597401	7.96741819381714	32.9119987487793	0.461219012737274	40.9990997314453
27.5071989744902	7.01359748840332	33.0120010375977	0.46246400475502	41.0990982055664
27.5905821472406	7.5358099937439	33.1119995117188	0.464693009853363	41.1991004943848
27.6740826666355	7.1436128616333	33.2120018005371	0.463975012302399	41.2990989685059
27.7569890022278	6.91187238693237	33.3120002746582	0.463975012302399	41.3991012573242
27.8406087309122	7.34985065460205	33.4119987487793	0.465941995382309	41.4990997314453
27.9236920177937	7.64228534698486	33.5120010375977	0.466924011707306	41.5990982055664
28.0070751905441	7.51343250274658	33.6119995117188	0.46791398525238	41.6991004943848
28.0906949192286	7.84980154037476	33.7120018005371	0.469698011875153	41.7990989685059
28.1740762293339	7.28450632095337	33.8120002746582	0.471450001001358	41.8991012573242
28.2570421695709	7.27797317504883	33.9119987487793	0.472694009542465	41.8991012573242
28.3407811075449	6.99217224121094	34.0120010375977	0.473605006933212	42.0999984741211
28.4238662570715	7.23216581344604	34.1119995117188	0.4757179915905	42.1991996765137
28.5073071718216	6.75214672088623	34.2120018005371	0.476963013410568	42.2990989685059
28.590451925993	6.92709589004517	34.3120002746582	0.477804005146027	42.3991012573242
28.6735352128744	7.34697341918945	34.4119987487793	0.480511009693146	42.4990997314453
28.7570357322693	7.81012773513794	34.5120010375977	0.480511009693146	42.5990982055664
28.8404785096645	8.14652347564697	34.6119995117188	0.481308996677399	42.6991004943848
28.9239194244146	7.47201251983643	34.7120018005371	0.48292601108551	42.7990989685059
29.0073025971651	7.40661525726318	34.8120002746582	0.48419201374054	42.8991012573242
29.0907435119152	7.7821478843689	34.9119987487793	0.485316008329391	42.9990997314453
29.1738864034414	7.49733066558838	35.0120010375977	0.486589014530182	43.1012992858887
29.257507994771	7.09924697875977	35.1119995117188	0.488822996616364	43.1991004943848
29.340710490942	7.26725769042969	35.2120018005371	0.488822996616364	43.2990989685059
29.4236168265343	6.68138408660889	35.3120002746582	0.490069001913071	43.3991012573242
29.5071173459291	7.72672986984253	35.4119987487793	0.49125400185585	43.4990997314453
29.5903813093901	7.56109142303467	35.5120010375977	0.492345988750458	43.5989990234375
29.6736434102058	7.57918691635132	35.6119995117188	0.493470996618271	43.6991004943848
29.7573823481798	6.99291896820068	35.7120018005371	0.494749009609222	43.798999786377
29.8404674977064	6.6788067817688	35.8120002746582	0.497184008359909	43.898998260498
29.9240872263908	7.18338108062744	35.9119987487793	0.497184008359909	43.9990997314453
30.007291585207	6.99673271179199	36.0120010375977	0.498154014348984	44.0989990234375
30.0904344767332	7.32584762573242	36.1119995117188	0.499354988336563	44.1991004943848
30.1736984401941	7.11123514175415	36.2120018005371	0.500724017620087	44.298999786377
30.2567221224308	7.64671468734741	36.3120002746582	0.503114998340607	44.3991012573242
30.3401630371809	7.66053867340088	36.4119987487793	0.503114998340607	44.4990005493164
30.4239038378	7.74197435379028	36.5120010375977	0.504199981689453	44.5989990234375
30.5073447525501	8.0334939956665	36.6119995117188	0.5052729845047	44.6990013122559
30.5911432951689	7.98940658569336	36.7120018005371	0.506484985351563	44.798999786377
30.6741688400507	8.18951606750488	36.8120002746582	0.507637023925781	44.8991012573242
30.7574309408665	7.90054321289063	36.9119987487793	0.508463025093079	44.9990005493164
30.8403372764587	8.34376049041748	37.0120010375977	0.510963022708893	45.1001014709473
30.9239570051432	7.53281164169312	37.1119995117188	0.510963022708893	45.1990013122559
31.0072805732489	8.01052665710449	37.2120018005371	0.512356996536255	45.298999786377
31.0906618833542	7.97783374786377	37.3120002746582	0.513463973999023	45.398998260498
31.1736278235912	8.06602382659912	37.4119987487793	0.514450013637543	45.4990005493164
31.2573648989201	8.6104564666748	37.5120010375977	0.516853988170624	45.5989990234375
31.3404500484467	8.167649269104	37.6119995117188	0.516853988170624	45.6990013122559
31.4239524304867	8.31266117095947	37.7120018005371	0.517503023147583	45.798999786377
31.5073914825916	8.3109884262085	37.8120002746582	0.519087970256805	45.898998260498
31.5906554460526	8.49999332427979	37.9119987487793	0.520242989063263	45.9990005493164
31.6739194095135	8.19774341583252	38.0120010375977	0.521458029747009	46.0989990234375
31.7574813961983	8.68328094482422	38.1119995117188	0.522418022155762	46.1990013122559
31.840443611145	9.0974292755127	38.2120018005371	0.52471399307251	46.298999786377
31.9237075746059	8.4251594543457	38.3120002746582	0.52471399307251	46.398998260498
32.0074483752251	8.75861930847168	38.4119987487793	0.525909006595612	46.4990005493164
32.0907086133957	8.64863586425781	38.5120010375977	0.527074992656708	46.5989990234375
32.1739725768566	8.35229301452637	38.6119995117188	0.528346002101898	46.6990013122559
32.2575345635414	8.79831409454346	38.7120018005371	0.53047502040863	46.798999786377
32.3407389223576	8.40656471252441	38.8120002746582	0.53047502040863	46.8992004394531
32.424058765173	8.66152381896973	38.9119987487793	0.533716022968292	46.9990005493164
32.5072631239891	8.85395908355713	39.0120010375977	0.533716022968292	47.0989990234375
32.5907655060291	8.97209072113037	39.1119995117188	0.534446001052856	47.1990013122559
32.6737873256207	8.87879848480225	39.2120018005371	0.535439014434814	47.298999786377
32.757468521595	7.88183212280273	39.3120002746582	0.536314010620117	47.398998260498
32.8407324850559	8.73836231231689	39.4119987487793	0.538092970848083	47.4990005493164
32.9239964485168	8.80885124206543	39.5120010375977	0.538092970848083	47.5989990234375
33.0072566866875	8.74982929229736	39.6119995117188	0.539376974105835	47.6988983154297
33.0906994640827	8.10686492919922	39.7120018005371	0.540464997291565	47.798900604248
33.1740230321884	8.24406051635742	39.8120002746582	0.541496992111206	47.8988990783691
33.2573428750038	8.71341705322266	39.9119987487793	0.543816983699799	47.9989013671875
33.3406068384647	8.85457420349121	40.0120010375977	0.543816983699799	48.0988998413086
33.4241688251495	8.22516059875488	40.1119995117188	0.54594099521637	48.1988983154297
33.5072502493858	8.84369564056396	40.2120018005371	0.54594099521637	48.298900604248
33.5903353989124	8.98403167724609	40.3120002746582	0.5468829870224	48.398998260498
33.6740761995316	9.16690826416016	40.4119987487793	0.547984004020691	48.4990005493164
33.7572209537029	9.22667121887207	40.5120010375977	0.549290001392365	48.5988998413086
33.8407792150974	8.60749435424805	40.6119995117188	0.550252020359039	48.6990013122559
33.9240431785583	8.9265308380127	40.7120018005371	0.551338016986847	48.798900604248
34.0073071420193	8.49114608764648	40.8120002746582	0.552235007286072	48.798900604248
34.0903885662556	8.76817226409912	40.9119987487793	0.553453981876373	48.9989013671875
34.1738313436508	8.90403747558594	41.0120010375977	0.554615020751953	49.0988998413086
34.2572145164013	8.81265926361084	41.1119995117188	0.555435001850128	49.1988983154297
34.340538084507	8.98162746429443	41.2120018005371	0.556466996669769	49.298900604248
34.4240963459015	8.72218608856201	41.3120002746582	0.559467017650604	49.3988990783691
34.5075391232967	8.88907146453857	41.4119987487793	0.559467017650604	49.4990005493164
34.5906838774681	8.7616081237793	41.5120010375977	0.559624016284943	49.5989990234375
34.6737653017044	9.16030693054199	41.6119995117188	0.560727000236511	49.6988983154297
34.7566716372967	8.67605781555176	41.7120018005371	0.561755001544952	49.798900604248
34.8405912518501	8.91725158691406	41.8120002746582	0.56447297334671	49.8988990783691
34.9240303039551	9.04043865203857	41.9119987487793	0.56447297334671	49.9989013671875
35.0074730813503	9.17652988433838	42.0120010375977	0.566556990146637	50.0988998413086
35.0910350680351	8.94920253753662	42.1119995117188	0.566556990146637	50.1988983154297
35.1741202175617	9.20217418670654	42.2120018005371	0.5677769780159	50.298900604248
35.2571420371532	9.00707244873047	42.3120002746582	0.569339990615845	50.3988990783691
35.3405848145485	9.50644969940186	42.4119987487793	0.57007497549057	50.4989013671875
35.4235507547855	9.34569263458252	42.5120010375977	0.571928024291992	50.5988998413086
35.5071686208248	9.25612926483154	42.6119995117188	0.571928024291992	50.6988983154297
35.5900749564171	9.88681125640869	42.7120018005371	0.574187994003296	50.798900604248
35.6742329895496	8.8987979888916	42.8120002746582	0.574187994003296	50.8988990783691
35.7571989297867	9.48763370513916	42.9119987487793	0.574872970581055	50.9987983703613
35.8403399586678	8.89391136169434	43.0120010375977	0.576318979263306	51.0988998413086
35.9240807592869	9.7232084274292	43.1119995117188	0.578217029571533	51.1990013122559
36.0071659088135	9.30982780456543	43.2120018005371	0.579183995723724	51.1990013122559
36.0903665423393	9.53335094451904	43.3120002746582	0.579393029212952	51.3988990783691
36.1740477383137	9.97872066497803	43.4119987487793	0.580331027507782	51.3988990783691
36.2573117017746	9.65545463562012	43.5120010375977	0.581987023353577	51.5988998413086
36.3405160605907	9.72729587554932	43.6119995117188	0.583148002624512	51.6988983154297
36.4238955080509	9.86271858215332	43.7120018005371	0.58383697271347	51.798900604248
36.5073382854462	10.0244960784912	43.8120002746582	0.58482700586319	51.8988990783691
36.5901850163937	10.2568044662476	43.9119987487793	0.586764991283417	51.9989013671875
36.6738624870777	9.857253074646	44.0120010375977	0.586764991283417	52.0988998413086
36.7573648691177	9.8846960067749	44.1119995117188	0.587751984596252	52.1988983154297
36.8405692279339	9.61541271209717	44.2120018005371	0.588751971721649	52.298900604248
36.9236506521702	9.97476482391357	44.3120002746582	0.589812994003296	52.3988990783691
37.007212638855	9.54657077789307	44.4119987487793	0.590808987617493	52.4989013671875
37.0904169976711	9.86066722869873	44.5120010375977	0.591839015483856	52.5988998413086
37.1739193797112	10.2084617614746	44.6119995117188	0.593716025352478	52.6987991333008
37.2572988271713	9.7457332611084	44.7120018005371	0.593716025352478	52.7988014221191
37.3407416045666	10.4232797622681	44.8120002746582	0.594250977039337	52.8987998962402
37.4240055680275	10.0163898468018	44.9119987487793	0.596045017242432	52.9989013671875
37.5071465969086	10.3189716339111	45.0120010375977	0.596937000751495	53.0988006591797
37.5906489789486	10.1866254806519	45.1119995117188	0.59891802072525	53.1987991333008
37.6737341284752	9.99916744232178	45.2120018005371	0.59891802072525	53.2988014221191
37.7573519945145	10.3851680755615	45.3120002746582	0.600853025913239	53.3988990783691
37.8404371440411	9.70412349700928	45.4119987487793	0.600853025913239	53.4987983703613
37.9238203167915	10.674861907959	45.5120010375977	0.601833999156952	53.5988006591797
38.0069650709629	9.81179332733154	45.6119995117188	0.602914988994598	53.6987991333008
38.0901657044888	9.92630100250244	45.7120018005371	0.603843986988068	53.7988014221191
38.1739065051079	10.0148487091064	45.8120002746582	0.60511302947998	53.9053993225098
38.2574088871479	10.2529850006104	45.9119987487793	0.60511302947998	53.9987983703613
38.3404903113842	10.2208862304688	46.0120010375977	0.606688976287842	54.0988006591797
38.4242311120033	10.378734588623	46.1119995117188	0.6076580286026	54.1987991333008
38.5071970522404	10.429144859314	46.2120018005371	0.608600974082947	54.3069000244141
38.5905206203461	10.3755731582642	46.3120002746582	0.610450983047485	54.3987998962402
38.6734828352928	10.968053817749	46.4119987487793	0.610450983047485	54.4987983703613
38.7572832405567	10.67360496521	46.5120010375977	0.612559974193573	54.5988006591797
38.8408452272415	11.0362968444824	46.6119995117188	0.612559974193573	54.6987991333008
38.9241650700569	10.7249088287354	46.7120018005371	0.613520979881287	54.7988014221191
39.0077866613865	10.2581615447998	46.8120002746582	0.61456698179245	54.8987998962402
39.0903949737549	11.0178480148315	46.9119987487793	0.615688979625702	54.9987983703613
39.1737185418606	10.5629634857178	47.0120010375977	0.617873013019562	55.0988006591797
39.2572171986103	10.2123546600342	47.1119995117188	0.617873013019562	55.1987991333008
39.3404811620712	11.0938396453857	47.2120018005371	0.619844019412994	55.2988014221191
39.424043148756	10.845118522644	47.3120002746582	0.619844019412994	55.4001007080078
39.5071245729923	11.101393699646	47.4119987487793	0.620472013950348	55.4986991882324
39.5912230014801	10.9140405654907	47.5120010375977	0.623265981674194	55.5988998413086
39.6741293370724	11.122166633606	47.6119995117188	0.623265981674194	55.6987991333008
39.7572703659534	11.316011428833	47.7120018005371	0.624750018119812	55.798698425293
39.8406535387039	11.088752746582	47.8120002746582	0.624750018119812	55.8987007141113
39.9238578975201	10.842435836792	47.9119987487793	0.625666975975037	55.9987983703613
40.0070622563362	10.9382638931274	48.0120010375977	0.627273976802826	56.0987014770508
40.090799331665	11.0809144973755	48.1119995117188	0.627273976802826	56.1987991333008
40.1740036904812	11.6050682067871	48.2120018005371	0.629274010658264	56.298698425293
40.2575060725212	11.0738296508789	48.3120002746582	0.629274010658264	56.3987998962402
40.3405874967575	11.2750177383423	48.4119987487793	0.631000995635986	56.4986991882324
40.4242686927319	11.2979421615601	48.5120010375977	0.631000995635986	56.5987014770508
40.5069962143898	10.8738508224487	48.6119995117188	0.631852984428406	56.6986999511719
40.5905582010746	10.5117692947388	48.7120018005371	0.633593022823334	56.798698425293
40.6739972531796	11.3151903152466	48.8120002746582	0.633593022823334	56.8987007141113
40.7570227980614	11.1847438812256	48.9119987487793	0.635625004768372	56.9986991882324
40.8405847847462	11.087347984314	49.0120010375977	0.635625004768372	57.0993003845215
40.9238450229168	11.0334033966064	49.1119995117188	0.63741797208786	57.1987991333008
41.0071685910225	11.5320129394531	49.2120018005371	0.63741797208786	57.2988014221191
41.0430245101452	-2.31231093406677	49.2550010681152	0.638889014720917	57.2988014221191